Traceback (most recent call last):
  File "/opt/hostedtoolcache/Python/3.10.18/x64/lib/python3.10/site-packages/nbclient/client.py", line 782, in _async_poll_for_reply
    msg = await ensure_async(self.kc.shell_channel.get_msg(timeout=new_timeout))
  File "/opt/hostedtoolcache/Python/3.10.18/x64/lib/python3.10/site-packages/jupyter_core/utils/__init__.py", line 214, in ensure_async
    result = await obj
  File "/opt/hostedtoolcache/Python/3.10.18/x64/lib/python3.10/site-packages/jupyter_client/channels.py", line 313, in get_msg
    raise Empty
_queue.Empty

During handling of the above exception, another exception occurred:

Traceback (most recent call last):
  File "/opt/hostedtoolcache/Python/3.10.18/x64/lib/python3.10/site-packages/jupyter_cache/executors/utils.py", line 58, in single_nb_execution
    executenb(
  File "/opt/hostedtoolcache/Python/3.10.18/x64/lib/python3.10/site-packages/nbclient/client.py", line 1319, in execute
    return NotebookClient(nb=nb, resources=resources, km=km, **kwargs).execute()
  File "/opt/hostedtoolcache/Python/3.10.18/x64/lib/python3.10/site-packages/jupyter_core/utils/__init__.py", line 165, in wrapped
    return loop.run_until_complete(inner)
  File "/opt/hostedtoolcache/Python/3.10.18/x64/lib/python3.10/asyncio/base_events.py", line 649, in run_until_complete
    return future.result()
  File "/opt/hostedtoolcache/Python/3.10.18/x64/lib/python3.10/site-packages/nbclient/client.py", line 709, in async_execute
    await self.async_execute_cell(
  File "/opt/hostedtoolcache/Python/3.10.18/x64/lib/python3.10/site-packages/nbclient/client.py", line 1005, in async_execute_cell
    exec_reply = await self.task_poll_for_reply
  File "/opt/hostedtoolcache/Python/3.10.18/x64/lib/python3.10/site-packages/nbclient/client.py", line 806, in _async_poll_for_reply
    error_on_timeout_execute_reply = await self._async_handle_timeout(timeout, cell)
  File "/opt/hostedtoolcache/Python/3.10.18/x64/lib/python3.10/site-packages/nbclient/client.py", line 856, in _async_handle_timeout
    raise CellTimeoutError.error_from_timeout_and_cell(
nbclient.exceptions.CellTimeoutError: A cell timed out while it was being executed, after 30 seconds.
The message was: Cell execution timed out.
Here is a preview of the cell contents:
-------------------
['# Apply a 2-ray multipath channel delta(t)-0.83 delta(t-3T/8)', 'mpath=[1, 0, 0, -0.87]   # May use easier mpath=[1, 0, 0, .45];', "print('Be Patient: This code may take several minutes to complete...')", '# time-domain multipath channel', 'h = np.convolve(np.convolve(prcos, pcmatch), mpath)']
...
['', 'for ii in range(10):', '    Eb2Naz[ii] = 2 * ii', '    # Compute the Analytical BER', '    Q[ii] = 3 * 0.5 * erfc(np.sqrt((2 * 10**(Eb2Naz[ii] * 0.1) / 5) / 2))']
-------------------

